<?xml version="1.0"?>
<robot name="test_robot">


<!-- **************************** Joint Properties ********************************* -->

<joint name="world_joint" type="fixed">
    <parent link = "world"/>
    <child link="base_corps_link_1"/>
    <origin rpy ="0. 0. 0." xyz = "0. 0. 0.4"/>
</joint>

<joint name="joint_chest_z" type="revolute">
    <parent link = "base_corps_link_1"/>
    <child link="link_virtual"/>
    <origin rpy ="0. 0. 0." xyz = "0.0 0.0 0.16"/>
    <axis xyz="0 0 1"/>
    <limit lower="-1.57" upper="1.57" effort="100.0" velocity="10.0"/>
    
</joint>


<!--joint name="joint_chest_y" type="revolute">
    <parent link = "link_virtual"/>
    <child link="base_corps_link_2"/>
    <origin rpy ="0. 0. 0." xyz = "0.0 0.0 0."/>
    <axis xyz="0 1 0"/>
    <limit lower="-1.57" upper="1.57" effort="100.0" velocity="10.0"/>

</joint-->

<joint name="joint_chest_y" type="fixed">
    <parent link = "link_virtual"/>
    <child link="base_corps_link_2"/>
    <origin rpy ="0. 0. 0." xyz = "0.0 0.0 0."/>
</joint>

<joint name="joint1" type="revolute">
  <origin xyz="0.00 0.075 0.1" rpy="0. 1.57 0.0"/>
  <parent link="base_corps_link_2"/>
  <child link="left_shoulder_psi_link"/>
  <axis xyz="0 0 1"/>
  <limit lower="-1.57" upper="1.57" effort="100.0" velocity="10.0"/>
</joint>

<joint name="joint2" type="revolute">
  <origin xyz="0.0 0. 0." rpy="0. 0. 0.0"/>
  <parent link="left_shoulder_psi_link"/>
  <child link="left_arm_shoulder"/>
  <axis xyz="0 -1 0"/>
  <limit lower="-1.57" upper="1.57" effort="100.0" velocity="10.0"/>
</joint>

<joint name="joint3" type="revolute">
  <origin xyz="0.2 0.025 0." rpy="1.57 0. 0.0"/>
  <parent link="left_arm_shoulder"/>
  <child link="left_forearm"/>
  <axis xyz="0 0 1"/>
  <limit lower="-1.57" upper="1.57" effort="100.0" velocity="10.0"/>
</joint>


<!-- **************************** Link Properties ********************************* -->
<link name="world"/> 

<link name="base_corps_link_1">
  <visual>
    <geometry>  
      <box size="0.15 0.15 0.15"/>
    </geometry>
    <origin xyz="0.0 0.0 0.075" rpy="0.0 0.0 0.0"/>
  </visual>

  <collision>
    <origin xyz="0.0 0.0 0.075" rpy="0.0 0.0 0.0"/>
    <geometry>  
      <box size="0.15 0.15 0.15"/>
    </geometry>
  </collision>

  <inertial>
    <mass value="20"/>
    <inertia ixx="10.0" ixy="0.0" ixz="0.0" iyy="10" iyz="0.0" izz="10.0"/>
  </inertial>
</link>

<link name="link_virtual">
  <visual>
    <geometry>
      <cylinder radius="0.01" length="0.075"/>
    </geometry>
    <origin xyz="0.0 0.0 0.0" rpy="-1.57 0.0 0.0"/>
  </visual>
  <inertial>
    <mass value="0.01"/>
    <inertia ixx="0.01" ixy="0.0" ixz="0.0" iyy="0.01" iyz="0.0" izz="0.01"/>
  </inertial>
</link>


<link name="base_corps_link_2">
  <visual>
    <geometry>
      <box size="0.15 0.15 0.15"/>
    </geometry>
    <origin xyz="0. 0. 0.075" rpy="0.0 0.0 0.0"/>
  </visual>

  <collision>
    <origin xyz="0. 0. 0.075" rpy="0.0 0.0 0.0"/>
    <geometry>  
      <box size="0.15 0.15 0.15"/>
    </geometry>
  </collision>

  <inertial>
    <mass value="1"/>
    <inertia ixx="1.0" ixy="0.0" ixz="0.0" iyy="1" iyz="0.0" izz="1.0"/>
  </inertial>
</link>



<link name="left_shoulder_psi_link" >
  <visual>
    <geometry>
      <cylinder radius="0.01" length="0.075"/>
    </geometry>
    <origin xyz="0.0 0.0 0.0" rpy="0 0.0 0.0"/>
  </visual>
  <inertial>
    <mass value="0.01"/>
    <inertia ixx="0.01" ixy="0.0" ixz="0.0" iyy="0.01" iyz="0.0" izz="0.01"/>
  </inertial>
</link>
<!--link name="link_virtual2">
  <visual>
    <geometry>
      <cylinder radius="0.01" length="0.075"/>
    </geometry>
    <origin xyz="0.0 0.0 0.0" rpy="-1.57 0.0 0.0"/>
  </visual>
</link-->

<link name="left_arm_shoulder">
  <visual>
    <geometry>
      <box size="0.2 0.05 0.05"/>
    </geometry>
    <origin xyz="0.1 0.03 0" rpy="0.0 0.0 0.0"/>
  </visual>

  <collision>
    <geometry>
      <box size="0.2 0.05 0.05"/>
    </geometry>
    <origin xyz="0.1 0.03 0" rpy="0.0 0.0 0.0"/>
  </collision>
   <inertial>
    <mass value="1"/>
    <inertia ixx="1.0" ixy="0.0" ixz="0.0" iyy="1" iyz="0.0" izz="1.0"/>
  </inertial>
</link>

<link name="left_forearm">
  <visual>
    <geometry>
      <box size="0.2 0.05 0.05"/>
    </geometry>
    <origin xyz="0.1 0.0 -0.002" rpy="0.0 0.0 0.0"/>
  </visual>


  <inertial>
    <mass value="1"/>
    <inertia ixx="1.0" ixy="0.0" ixz="0.0" iyy="1" iyz="0.0" izz="1.0"/>
  </inertial>
  
  <collision>
    <geometry>
      <box size="0.2 0.05 0.05"/>
    </geometry>
    <origin xyz="0.1 0.0 -0.002" rpy="0.0 0.0 0.0"/>
  </collision> 
</link>

<!-- **************************** Gazebo Properties ********************************* -->
<gazebo reference="base_corps_link_1">
   <material>Gazebo/White</material>
</gazebo>
<gazebo reference="link_virtual">
   <material>Gazebo/White</material>
</gazebo>
<gazebo reference="base_corps_link_2">
   <material>Gazebo/White</material>
</gazebo>


<gazebo reference="left_shoulder_psi_link">
   <material>Gazebo/White</material>
</gazebo>

<gazebo reference="left_arm_shoulder">
   <material>Gazebo/White</material>
</gazebo>

<gazebo reference="left_forearm">
   <material>Gazebo/White</material>
</gazebo>


<!-- Transmissions for ROS Control -->
  <!--transmission name="tran1">
    <type>transmission_interface/SimpleTransmission</type>
    <joint name="joint_chest_z">
      <hardwareInterface>PositionJointInterface</hardwareInterface>
    </joint>
    <actuator name="motor1">
      <hardwareInterface>PositionJointInterface</hardwareInterface>
      <mechanicalReduction>1</mechanicalReduction>
    </actuator>
  </transmission>

  <transmission name="tran2">
    <type>transmission_interface/SimpleTransmission</type>
    <joint name="joint_chest_y">
      <hardwareInterface>PositionJointInterface</hardwareInterface>
    </joint>
    <actuator name="motor2">
      <hardwareInterface>PositionJointInterface</hardwareInterface>
      <mechanicalReduction>1</mechanicalReduction>
    </actuator>
  </transmission>

  <transmission name="tran3">
    <type>transmission_interface/SimpleTransmission</type>
    <joint name="joint1">
      <hardwareInterface>PositionJointInterface</hardwareInterface>
    </joint>
    <actuator name="motor3">
      <hardwareInterface>PositionJointInterface</hardwareInterface>
      <mechanicalReduction>1</mechanicalReduction>
    </actuator>
  </transmission>

  <transmission name="tran4">
    <type>transmission_interface/SimpleTransmission</type>
    <joint name="joint2">
      <hardwareInterface>PositionJointInterface</hardwareInterface>
    </joint>
    <actuator name="motor4">
      <hardwareInterface>PositionJointInterface</hardwareInterface>
      <mechanicalReduction>1</mechanicalReduction>
    </actuator>
  </transmission>

  <transmission name="tran5">
    <type>transmission_interface/SimpleTransmission</type>
    <joint name="joint3">
      <hardwareInterface>PositionJointInterface</hardwareInterface>
    </joint>
    <actuator name="motor5">
      <hardwareInterface>PositionJointInterface</hardwareInterface>
      <mechanicalReduction>1</mechanicalReduction>
    </actuator>
  </transmission-->

   <gazebo>
    <plugin filename="libgazebo_ros_control.so" name="gazebo_ros_control">
      <robotNamespace>/robot</robotNamespace>
      <robotSimType>gazebo_ros_control/DefaultRobotHWSim</robotSimType>
    </plugin>
  </gazebo>
</robot>
