<?xml version="1.0"?>
<robot name="arm">



<link name="base_link">
  <visual>
    <geometry>
      <box size="0.15 0.1 0.8"/>
    </geometry>
  </visual>
</link>

  <!-- <link name="right_upper_arm">
    <visual>
      <geometry>
        <box size="0.075 0.05 0.3"/>
      </geometry>
      <origin rpy="0 0 0" xyz="0 0 -0.15"/>
    </visual>
  </link> -->

  <link name="right_upper_arm_virtual_1">
    <visual>
      <geometry>
        <box size="0.001 0.001 0.001"/>
      </geometry>
      <origin rpy="1.57 -1.57 1.57" xyz="0 0 -0.15"/>
    </visual>
  </link>

  <joint name="base_to_virtual1" type="continuous">
    <parent link="base_link"/>
    <child link="right_upper_arm_virtual_1"/>
    <origin xyz="-0.05 -0.0725 0.4"/> 
    <axis xyz="0 -1 0"/>
  </joint>

<!-- 
  <joint name="base_to_right_leg" type="fixed">
    <parent link="base_link"/>
    <child link="right_upper_arm"/>
    <origin xyz="-0.05 -0.0725 0.4"/> 
    <axis xyz="0 0 1"/>
  </joint> -->


  </robot>